<?xml version="1.0" encoding="utf-8"?>
<!-- =================================================================================== -->
<!-- |    This document was autogenerated by xacro from robot_kuka.xacro               | -->
<!-- |    EDITING THIS FILE BY HAND IS NOT RECOMMENDED                                 | -->
<!-- =================================================================================== -->
<robot name="robot_kuka">
  <link name="base_link">
    <visual>
      <geometry>
        <box size="10 0.6 0.02"/>
      </geometry>
      <origin rpy="0 0 0" xyz="0 0 0"/>
      <material name="yellow">
        <color rgba="1 1 0 1"/>
      </material>
    </visual>
  </link>
  <joint name="joint0" type="prismatic">
    <parent link="base_link"/>
    <child link="link1"/>
    <origin xyz="0 0 0"/>
    <axis xyz="1 0 0"/>
    <orient rpy="0 0 0"/>
    <limit effort="176" lower="-5" upper="5" velocity="0.1">
		</limit>
    <dynamics damping="50" friction="1"/>
  </joint>
  <link name="link1">
    <visual>
      <geometry>
        <cylinder length="0.2" radius="0.05"/>
      </geometry>
      <material name="red">
        <color rgba="0 0 1 1"/>
      </material>
      <origin xyz="0 0 0.1"/>
      <orient rpy="0 0 0"/>
    </visual>
  </link>
  <joint name="joint1" type="revolute">
    <parent link="link1"/>
    <child link="link2"/>
    <origin xyz="0 0 0.2"/>
    <axis xyz="0 1 0"/>
    <orient rpy="0 0 0"/>
    <limit effort="176" lower="-2.96" upper="2.96" velocity="0.1">
		</limit>
    <dynamics damping="50" friction="1"/>
  </joint>
  <link name="link2">
    <visual>
      <geometry>
        <cylinder length="0.2" radius="0.05"/>
      </geometry>
      <material name="red">
        <color rgba="0 0 1 1"/>
      </material>
      <origin xyz="0 0 0.1"/>
      <orient rpy="0 0 0"/>
    </visual>
  </link>
  <joint name="joint2" type="revolute">
    <parent link="link2"/>
    <child link="link3"/>
    <origin xyz="0 0 0.2"/>
    <axis xyz="0 0 1"/>
    <orient rpy="1.57 0 3.14"/>
    <limit effort="176" lower="-2.09" upper="2.09" velocity="0.1">
		</limit>
    <dynamics damping="50" friction="1"/>
  </joint>
  <link name="link3">
    <visual>
      <geometry>
        <cylinder length="0.2" radius="0.05"/>
      </geometry>
      <material name="red">
        <color rgba="0 0 1 1"/>
      </material>
      <origin xyz="0 0 0.1"/>
      <orient rpy="0 0 0"/>
    </visual>
  </link>
  <joint name="joint3" type="revolute">
    <parent link="link3"/>
    <child link="link4"/>
    <origin xyz="0 0 0.2"/>
    <axis xyz="0 1 0"/>
    <orient rpy="3.14 0 3.14"/>
    <limit effort="110" lower="-2.96" upper="2.96" velocity="0.1">
		</limit>
    <dynamics damping="50" friction="1"/>
  </joint>
  <link name="link4">
    <visual>
      <geometry>
        <cylinder length="0.2" radius="0.05"/>
      </geometry>
      <material name="red">
        <color rgba="0 0 1 1"/>
      </material>
      <origin xyz="0 0 0.1"/>
      <orient rpy="0 0 0"/>
    </visual>
  </link>
  <joint name="joint4" type="revolute">
    <parent link="link4"/>
    <child link="link5"/>
    <origin xyz="0 0 0.2"/>
    <axis xyz="0 0 1"/>
    <orient rpy="3.14 0 0"/>
    <limit effort="110" lower="-2.09" upper="2.09" velocity="0.1">
		</limit>
    <dynamics damping="50" friction="1"/>
  </joint>
  <link name="link5">
    <visual>
      <geometry>
        <cylinder length="0.2" radius="0.05"/>
      </geometry>
      <material name="red">
        <color rgba="0 0 1 1"/>
      </material>
      <origin xyz="0 0 0.1"/>
      <orient rpy="0 0 0"/>
    </visual>
  </link>
  <joint name="joint5" type="revolute">
    <parent link="link5"/>
    <child link="link6"/>
    <origin xyz="0 0 0.2"/>
    <axis xyz="0 1 0"/>
    <orient rpy="-3.14 3.14 0"/>
    <limit effort="110" lower="-2.96" upper="2.96" velocity="0.1">
		</limit>
    <dynamics damping="50" friction="1"/>
  </joint>
  <link name="link6">
    <visual>
      <geometry>
        <cylinder length="0.2" radius="0.05"/>
      </geometry>
      <material name="red">
        <color rgba="0 0 1 1"/>
      </material>
      <origin xyz="0 0 0.1"/>
      <orient rpy="0 0 0"/>
    </visual>
  </link>
  <joint name="joint6" type="revolute">
    <parent link="link6"/>
    <child link="link7"/>
    <origin xyz="0 0 0.2"/>
    <axis xyz="0 0 1"/>
    <orient rpy="3.14 0 0"/>
    <limit effort="40" lower="-2.09" upper="2.09" velocity="0.1">
		</limit>
    <dynamics damping="50" friction="1"/>
  </joint>
  <link name="link7">
    <visual>
      <geometry>
        <cylinder length="0.2" radius="0.05"/>
      </geometry>
      <material name="red">
        <color rgba="0 0 1 1"/>
      </material>
      <origin xyz="0 0 0.1"/>
      <orient rpy="0 0 0"/>
    </visual>
  </link>
  <joint name="joint7" type="revolute">
    <parent link="link7"/>
    <child link="link_ee"/>
    <origin xyz="0 0 0.2"/>
    <axis xyz="0 1 0"/>
    <orient rpy="-3.14 3.14 0"/>
    <limit effort="40" lower="-3.05" upper="3.05" velocity="0.1">
		</limit>
    <dynamics damping="50" friction="1"/>
  </joint>
  <link name="link_ee">
    <visual>
      <geometry>
        <cylinder length="0.2" radius="0.05"/>
      </geometry>
      <material name="red">
        <color rgba="0 0 1 1"/>
      </material>
      <origin xyz="0 0 0.1"/>
      <orient rpy="0 0 0"/>
    </visual>
  </link>
</robot>

